Workbook

Sheet Indicadores
A1: IAP - Indicador de Aderência ao Processo (70% a 100%)
A2: Fases e iterações (sprints) | B2: Aderência (%)
A3: Iniciação | B3: ='Ver-Iniciação1'!$F$2 -> 1
A4: Elaboração | B4: ='Ver-Elaboração1'!$F$2 -> 0.82608696
A5: Construção | B5: ='Ver-Construção1'!$F$2 -> 1.0416667
A6: Transição | B6: ='Ver-Transição1'!$F$2 -> #DIV/0!

Sheet Detalhado
A1: DESCRIÇÃO | B1: SIM | C1: PARCIALMENTE | D1: NÃO | E1: N/A | N1: DESCRIÇÃO | O1: SIM | P1: PARCIALMENTE | Q1: NÃO | R1: N/A
A2: documentos não padronizados (templates, guias, leis, etc.) | B2: =('Ver-Iniciação1'!$G$5/SUM('Ver-Iniciação1'!$G$5:$J$5)) -> 0 | C2: =('Ver-Iniciação1'!$H$5/SUM('Ver-Iniciação1'!$G$5:$J$5)) -> 0 | D2: =('Ver-Iniciação1'!$I$5/SUM('Ver-Iniciação1'!$G$5:$J$5)) -> 0 | E2: =('Ver-Iniciação1'!$J$5/SUM('Ver-Iniciação1'!$G$5:$J$5)) -> 1 | N2: visão | O2: =('Ver-Elaboração1'!$G$6/SUM('Ver-Elaboração1'!$G$6:$J$6)) -> 0 | P2: =('Ver-Elaboração1'!$H$6/SUM('Ver-Elaboração1'!$G$6:$J$6)) -> 0 | Q2: =('Ver-Elaboração1'!$I$6/SUM('Ver-Elaboração1'!$G$6:$J$6)) -> 1 | R2: =('Ver-Elaboração1'!$J$6/SUM('Ver-Elaboração1'!$G$6:$J$6)) -> 0
A3: visão | B3: =('Ver-Iniciação1'!$G$7/SUM('Ver-Iniciação1'!$G$7:$J$7)) -> 1 | C3: =('Ver-Iniciação1'!$H$7/SUM('Ver-Iniciação1'!$G$7:$J$7)) -> 0 | D3: =('Ver-Iniciação1'!$I$7/SUM('Ver-Iniciação1'!$G$7:$J$7)) -> 0 | E3: =('Ver-Iniciação1'!$J$7/SUM('Ver-Iniciação1'!$G$7:$J$7)) -> 0 | N3: modelo de caso de uso | O3: =('Ver-Elaboração1'!$G$8/SUM('Ver-Elaboração1'!$G$8:$J$8)) -> 1 | P3: =('Ver-Elaboração1'!$H$8/SUM('Ver-Elaboração1'!$G$8:$J$8)) -> 0 | Q3: =('Ver-Elaboração1'!$I$8/SUM('Ver-Elaboração1'!$G$8:$J$8)) -> 0 | R3: =('Ver-Elaboração1'!$J$8/SUM('Ver-Elaboração1'!$G$8:$J$8)) -> 0
A4: modelo de caso de uso | B4: =('Ver-Iniciação1'!$G$13/SUM('Ver-Iniciação1'!$G$13:$J$13)) -> 0.8 | C4: =('Ver-Iniciação1'!$H$13/SUM('Ver-Iniciação1'!$G$13:$J$13)) -> 0 | D4: =('Ver-Iniciação1'!$I$13/SUM('Ver-Iniciação1'!$G$13:$J$13)) -> 0 | E4: =('Ver-Iniciação1'!$J$13/SUM('Ver-Iniciação1'!$G$13:$J$13)) -> 0.2 | N4: especificações de requisitos (casos de uso e/ou histórias do usuário)? | O4: =('Ver-Elaboração1'!$G$11/SUM('Ver-Elaboração1'!$G$11:$J$11)) -> 0.75 | P4: =('Ver-Elaboração1'!$H$11/SUM('Ver-Elaboração1'!$G$11:$J$11)) -> 0 | Q4: =('Ver-Elaboração1'!$I$11/SUM('Ver-Elaboração1'!$G$11:$J$11)) -> 0 | R4: =('Ver-Elaboração1'!$J$11/SUM('Ver-Elaboração1'!$G$11:$J$11)) -> 0.25
A5: especificações de requisitos (casos de uso e/ou histórias do usuário)? | B5: =('Ver-Iniciação1'!$G$19/SUM('Ver-Iniciação1'!$G$19:$J$19)) -> 1 | C5: =('Ver-Iniciação1'!$H$19/SUM('Ver-Iniciação1'!$G$19:$J$19)) -> 0 | D5: =('Ver-Iniciação1'!$I$19/SUM('Ver-Iniciação1'!$G$19:$J$19)) -> 0 | E5: =('Ver-Iniciação1'!$J$19/SUM('Ver-Iniciação1'!$G$19:$J$19)) -> 0 | N5: glossário | O5: =('Ver-Elaboração1'!$G$16/SUM('Ver-Elaboração1'!$G$16:$J$16)) -> 0 | P5: =('Ver-Elaboração1'!$H$16/SUM('Ver-Elaboração1'!$G$16:$J$16)) -> 0 | Q5: =('Ver-Elaboração1'!$I$16/SUM('Ver-Elaboração1'!$G$16:$J$16)) -> 0 | R5: =('Ver-Elaboração1'!$J$16/SUM('Ver-Elaboração1'!$G$16:$J$16)) -> 1
A6: glossário | B6: =('Ver-Iniciação1'!$G$22/SUM('Ver-Iniciação1'!$G$22:$J$22)) -> 0 | C6: =('Ver-Iniciação1'!$H$22/SUM('Ver-Iniciação1'!$G$22:$J$22)) -> 0 | D6: =('Ver-Iniciação1'!$I$22/SUM('Ver-Iniciação1'!$G$22:$J$22)) -> 0 | E6: =('Ver-Iniciação1'!$J$22/SUM('Ver-Iniciação1'!$G$22:$J$22)) -> 1 | N6: atas de reuniões | O6: =('ver-elaboração1'!#ref!/SUM('ver-elaboração1'!#ref!:'ver-elaboração1'!#ref!)) -> #VALUE! | P6: =('ver-elaboração1'!#ref!/SUM('ver-elaboração1'!#ref!:'ver-elaboração1'!#ref!)) -> #VALUE! | Q6: =('ver-elaboração1'!#ref!/SUM('ver-elaboração1'!#ref!:'ver-elaboração1'!#ref!)) -> #VALUE! | R6: =('ver-elaboração1'!#ref!/SUM('ver-elaboração1'!#ref!:'ver-elaboração1'!#ref!)) -> #VALUE!
A7: atas de reuniões | B7: =('Ver-Iniciação1'!$G$25/SUM('Ver-Iniciação1'!$G$25:$J$25)) -> 0 | C7: =('Ver-Iniciação1'!$H$25/SUM('Ver-Iniciação1'!$G$25:$J$25)) -> 0 | D7: =('Ver-Iniciação1'!$I$25/SUM('Ver-Iniciação1'!$G$25:$J$25)) -> 0 | E7: =('Ver-Iniciação1'!$J$25/SUM('Ver-Iniciação1'!$G$25:$J$25)) -> 1 | N7: modelo de arquitetura | O7: =('Ver-Elaboração1'!$G$18/SUM('Ver-Elaboração1'!$G$18:$J$18)) -> 0.75 | P7: =('Ver-Elaboração1'!$H$18/SUM('Ver-Elaboração1'!$G$18:$J$18)) -> 0 | Q7: =('Ver-Elaboração1'!$I$18/SUM('Ver-Elaboração1'!$G$18:$J$18)) -> 0 | R7: =('Ver-Elaboração1'!$J$18/SUM('Ver-Elaboração1'!$G$18:$J$18)) -> 0.25
A8: termo de abertura do projeto | B8: =('ver-iniciação1'!#ref!/SUM('ver-iniciação1'!#ref!:'ver-iniciação1'!#ref!)) -> #VALUE! | C8: =('ver-iniciação1'!#ref!/SUM('ver-iniciação1'!#ref!:'ver-iniciação1'!#ref!)) -> #VALUE! | D8: =('ver-iniciação1'!#ref!/SUM('ver-iniciação1'!#ref!:'ver-iniciação1'!#ref!)) -> #VALUE! | E8: =('ver-iniciação1'!#ref!/SUM('ver-iniciação1'!#ref!:'ver-iniciação1'!#ref!)) -> #VALUE! | N8: guia de implementação | O8: =('ver-elaboração1'!#ref!/SUM('ver-elaboração1'!#ref!:'ver-elaboração1'!#ref!)) -> #VALUE! | P8: =('ver-elaboração1'!#ref!/SUM('ver-elaboração1'!#ref!:'ver-elaboração1'!#ref!)) -> #VALUE! | Q8: =('ver-elaboração1'!#ref!/SUM('ver-elaboração1'!#ref!:'ver-elaboração1'!#ref!)) -> #VALUE! | R8: =('ver-elaboração1'!#ref!/SUM('ver-elaboração1'!#ref!:'ver-elaboração1'!#ref!)) -> #VALUE!
A9: caso de desenvolvimento | B9: =('ver-iniciação1'!#ref!/SUM('ver-iniciação1'!#ref!:'ver-iniciação1'!#ref!)) -> #VALUE! | C9: =('ver-iniciação1'!#ref!/SUM('ver-iniciação1'!#ref!:'ver-iniciação1'!#ref!)) -> #VALUE! | D9: =('ver-iniciação1'!#ref!/SUM('ver-iniciação1'!#ref!:'ver-iniciação1'!#ref!)) -> #VALUE! | E9: =('ver-iniciação1'!#ref!/SUM('ver-iniciação1'!#ref!:'ver-iniciação1'!#ref!)) -> #VALUE! | N9: codigo fonte | O9: =('Ver-Elaboração1'!$G$23/SUM('Ver-Elaboração1'!$G$23:$J$23)) -> 0.6 | P9: =('Ver-Elaboração1'!$H$23/SUM('Ver-Elaboração1'!$G$23:$J$23)) -> 0 | Q9: =('Ver-Elaboração1'!$I$23/SUM('Ver-Elaboração1'!$G$23:$J$23)) -> 0 | R9: =('Ver-Elaboração1'!$J$23/SUM('Ver-Elaboração1'!$G$23:$J$23)) -> 0.4
A10: planilha de planejamento e controle do projeto | B10: =('Ver-Iniciação1'!$G$28/SUM('Ver-Iniciação1'!$G$28:$J$28)) -> 1 | C10: =('Ver-Iniciação1'!$H$28/SUM('Ver-Iniciação1'!$G$28:$J$28)) -> 0 | D10: =('Ver-Iniciação1'!$I$28/SUM('Ver-Iniciação1'!$G$28:$J$28)) -> 0 | E10: =('Ver-Iniciação1'!$J$28/SUM('Ver-Iniciação1'!$G$28:$J$28)) -> 0 | N10: planilha de planejamento e controle do projeto | O10: =('Ver-Elaboração1'!$G$29/SUM('Ver-Elaboração1'!$G$29:$J$29)) -> 0.66666667 | P10: =('Ver-Elaboração1'!$H$29/SUM('Ver-Elaboração1'!$G$29:$J$29)) -> 0 | Q10: =('Ver-Elaboração1'!$I$29/SUM('Ver-Elaboração1'!$G$29:$J$29)) -> 0.33333333 | R10: =('Ver-Elaboração1'!$J$29/SUM('Ver-Elaboração1'!$G$29:$J$29)) -> 0
A11: repositório (itens de configuração) | B11: =('Ver-Iniciação1'!$G$37/SUM('Ver-Iniciação1'!$G$37:$J$37)) -> 1 | C11: =('Ver-Iniciação1'!$H$37/SUM('Ver-Iniciação1'!$G$37:$J$37)) -> 0 | D11: =('Ver-Iniciação1'!$I$37/SUM('Ver-Iniciação1'!$G$37:$J$37)) -> 0 | E11: =('Ver-Iniciação1'!$J$37/SUM('Ver-Iniciação1'!$G$37:$J$37)) -> 0 | N11: repositório (itens de configuração) | O11: =('Ver-Elaboração1'!$G$36/SUM('Ver-Elaboração1'!$G$36:$J$36)) -> 1 | P11: =('Ver-Elaboração1'!$H$36/SUM('Ver-Elaboração1'!$G$36:$J$36)) -> 0 | Q11: =('Ver-Elaboração1'!$I$36/SUM('Ver-Elaboração1'!$G$36:$J$36)) -> 0 | R11: =('Ver-Elaboração1'!$J$36/SUM('Ver-Elaboração1'!$G$36:$J$36)) -> 0
A12: requisição de mudanças | B12: =('ver-iniciação1'!#ref!/SUM('ver-iniciação1'!#ref!:'ver-iniciação1'!#ref!)) -> #VALUE! | C12: =('ver-iniciação1'!#ref!/SUM('ver-iniciação1'!#ref!:'ver-iniciação1'!#ref!)) -> #VALUE! | D12: =('ver-iniciação1'!#ref!/SUM('ver-iniciação1'!#ref!:'ver-iniciação1'!#ref!)) -> #VALUE! | E12: =('ver-iniciação1'!#ref!/SUM('ver-iniciação1'!#ref!:'ver-iniciação1'!#ref!)) -> #VALUE! | N12: requisição de mudanças | O12: =('Ver-Elaboração1'!$G$40/SUM('Ver-Elaboração1'!$G$40:$J$40)) -> 0.5 | P12: =('Ver-Elaboração1'!$H$40/SUM('Ver-Elaboração1'!$G$40:$J$40)) -> 0 | Q12: =('Ver-Elaboração1'!$I$40/SUM('Ver-Elaboração1'!$G$40:$J$40)) -> 0.5 | R12: =('Ver-Elaboração1'!$J$40/SUM('Ver-Elaboração1'!$G$40:$J$40)) -> 0
A22: DESCRIÇÃO | B22: SIM | C22: PARCIALMENTE | D22: NÃO | E22: N/A
A23: visão | B23: =('Ver-Construção1'!$G$6/SUM('Ver-Construção1'!$G$6:$J$6)) -> 0 | C23: =('Ver-Construção1'!$H$6/SUM('Ver-Construção1'!$G$6:$J$6)) -> 0 | D23: =('Ver-Construção1'!$I$6/SUM('Ver-Construção1'!$G$6:$J$6)) -> 0 | E23: =('Ver-Construção1'!$J$6/SUM('Ver-Construção1'!$G$6:$J$6)) -> 1
A24: modelo de caso de uso | B24: =('Ver-Construção1'!$G$8/SUM('Ver-Construção1'!$G$8:$J$8)) -> 1 | C24: =('Ver-Construção1'!$H$8/SUM('Ver-Construção1'!$G$8:$J$8)) -> 0 | D24: =('Ver-Construção1'!$I$8/SUM('Ver-Construção1'!$G$8:$J$8)) -> 0 | E24: =('Ver-Construção1'!$J$8/SUM('Ver-Construção1'!$G$8:$J$8)) -> 0 | M24: DESCRIÇÃO | N24: SIM | O24: PARCIALMENTE | P24: NÃO | Q24: N/A
A25: especificações de requisitos (casos de uso e/ou histórias do usuário)? | B25: =('Ver-Construção1'!$G$10/SUM('Ver-Construção1'!$G$10:$J$10)) -> 1 | C25: =('Ver-Construção1'!$G$10/SUM('Ver-Construção1'!$G$10:$J$10)) -> 1 | D25: =('Ver-Construção1'!$I$10/SUM('Ver-Construção1'!$G$10:$J$10)) -> 0 | E25: =('Ver-Construção1'!$J$10/SUM('Ver-Construção1'!$G$10:$J$10)) -> 0 | M25: visão | N25: =('Ver-Transição1'!$G$6/SUM('Ver-Transição1'!$G$6:$J$6)) -> #DIV/0! | O25: =('Ver-Transição1'!$H$6/SUM('Ver-Transição1'!$G$6:$J$6)) -> #DIV/0! | P25: =('Ver-Transição1'!$I$6/SUM('Ver-Transição1'!$G$6:$J$6)) -> #DIV/0! | Q25: =('Ver-Transição1'!$J$6/SUM('Ver-Transição1'!$G$6:$J$6)) -> #DIV/0!
A26: glossário | B26: =('Ver-Construção1'!$G$14/SUM('Ver-Construção1'!$G$14:$J$14)) -> 0 | C26: =('Ver-Construção1'!$H$14/SUM('Ver-Construção1'!$G$14:$J$14)) -> 0 | D26: =('Ver-Construção1'!$I$14/SUM('Ver-Construção1'!$G$14:$J$14)) -> 0 | E26: =('Ver-Construção1'!$J$14/SUM('Ver-Construção1'!$G$14:$J$14)) -> 1 | M26: modelo de caso de uso | N26: =('Ver-Transição1'!$G$8/SUM('Ver-Transição1'!$G$8:$J$8)) -> #DIV/0! | O26: =('Ver-Transição1'!$H$8/SUM('Ver-Transição1'!$G$8:$J$8)) -> #DIV/0! | P26: =('Ver-Transição1'!$I$8/SUM('Ver-Transição1'!$G$8:$J$8)) -> #DIV/0! | Q26: =('Ver-Transição1'!$J$8/SUM('Ver-Transição1'!$G$8:$J$8)) -> #DIV/0!
A27: atas de reuniões | B27: =('ver-construção1'!#ref!/SUM('ver-construção1'!#ref!:'ver-construção1'!#ref!)) -> #VALUE! | C27: =('ver-construção1'!#ref!/SUM('ver-construção1'!#ref!:'ver-construção1'!#ref!)) -> #VALUE! | D27: =('ver-construção1'!#ref!/SUM('ver-construção1'!#ref!:'ver-construção1'!#ref!)) -> #VALUE! | E27: =('ver-construção1'!#ref!/SUM('ver-construção1'!#ref!:'ver-construção1'!#ref!)) -> #VALUE! | M27: especificações de requisitos (casos de uso e/ou histórias do usuário)? | N27: =('Ver-Transição1'!$G$10/SUM('Ver-Transição1'!$G$10:$J$10)) -> #DIV/0! | O27: =('Ver-Transição1'!$H$10/SUM('Ver-Transição1'!$G$10:$J$10)) -> #DIV/0! | P27: =('Ver-Transição1'!$I$10/SUM('Ver-Transição1'!$G$10:$J$10)) -> #DIV/0! | Q27: =('Ver-Transição1'!$J$10/SUM('Ver-Transição1'!$G$10:$J$10)) -> #DIV/0!
A28: modelo de arquitetura | B28: =('Ver-Construção1'!$G$16/SUM('Ver-Construção1'!$G$16:$J$16)) -> 1 | C28: =('Ver-Construção1'!$H$16/SUM('Ver-Construção1'!$G$16:$J$16)) -> 0 | D28: =('Ver-Construção1'!$I$16/SUM('Ver-Construção1'!$G$16:$J$16)) -> 0 | E28: =('Ver-Construção1'!$J$16/SUM('Ver-Construção1'!$G$16:$J$16)) -> 0 | M28: glossário | N28: =('Ver-Transição1'!$G$14/SUM('Ver-Transição1'!$G$14:$J$14)) -> #DIV/0! | O28: =('Ver-Transição1'!$H$14/SUM('Ver-Transição1'!$G$14:$J$14)) -> #DIV/0! | P28: =('Ver-Transição1'!$I$14/SUM('Ver-Transição1'!$G$14:$J$14)) -> #DIV/0! | Q28: =('Ver-Transição1'!$J$14/SUM('Ver-Transição1'!$G$14:$J$14)) -> #DIV/0!
A29: guia de implementação | B29: =('ver-construção1'!#ref!/SUM('ver-construção1'!#ref!:'ver-construção1'!#ref!)) -> #VALUE! | C29: =('ver-construção1'!#ref!/SUM('ver-construção1'!#ref!:'ver-construção1'!#ref!)) -> #VALUE! | D29: =('ver-construção1'!#ref!/SUM('ver-construção1'!#ref!:'ver-construção1'!#ref!)) -> #VALUE! | E29: =('ver-construção1'!#ref!/SUM('ver-construção1'!#ref!:'ver-construção1'!#ref!)) -> #VALUE! | M29: atas de reuniões | N29: =('ver-transição1'!#ref!/SUM('ver-transição1'!#ref!:'ver-transição1'!#ref!)) -> #VALUE! | O29: =('ver-transição1'!#ref!/SUM('ver-transição1'!#ref!:'ver-transição1'!#ref!)) -> #VALUE! | P29: =('ver-transição1'!#ref!/SUM('ver-transição1'!#ref!:'ver-transição1'!#ref!)) -> #VALUE! | Q29: =('ver-transição1'!#ref!/SUM('ver-transição1'!#ref!:'ver-transição1'!#ref!)) -> #VALUE!
A30: codigo fonte | B30: =('Ver-Construção1'!$G$18/SUM('Ver-Construção1'!$G$18:$J$18)) -> 1 | C30: =('Ver-Construção1'!$H$18/SUM('Ver-Construção1'!$G$18:$J$18)) -> 0 | D30: =('Ver-Construção1'!$I$18/SUM('Ver-Construção1'!$G$18:$J$18)) -> 0 | E30: =('Ver-Construção1'!$J$18/SUM('Ver-Construção1'!$G$18:$J$18)) -> 0 | M30: modelo de arquitetura | N30: =('Ver-Transição1'!$G$16/SUM('Ver-Transição1'!$G$16:$J$16)) -> #DIV/0! | O30: =('Ver-Transição1'!$H$16/SUM('Ver-Transição1'!$G$16:$J$16)) -> #DIV/0! | P30: =('Ver-Transição1'!$I$16/SUM('Ver-Transição1'!$G$16:$J$16)) -> #DIV/0! | Q30: =('Ver-Transição1'!$J$16/SUM('Ver-Transição1'!$G$16:$J$16)) -> #DIV/0!
A31: roteiro de testes | B31: =('Ver-Construção1'!$G$24/SUM('Ver-Construção1'!$G$24:$J$24)) -> 1 | C31: =('Ver-Construção1'!$H$24/SUM('Ver-Construção1'!$G$24:$J$24)) -> 0 | D31: =('Ver-Construção1'!$I$24/SUM('Ver-Construção1'!$G$24:$J$24)) -> 0 | E31: =('Ver-Construção1'!$J$24/SUM('Ver-Construção1'!$G$24:$J$24)) -> 0 | M31: codigo fonte | N31: =('Ver-Transição1'!$G$18/SUM('Ver-Transição1'!$G$18:$J$18)) -> #DIV/0! | O31: =('Ver-Transição1'!$H$18/SUM('Ver-Transição1'!$G$18:$J$18)) -> #DIV/0! | P31: =('Ver-Transição1'!$I$18/SUM('Ver-Transição1'!$G$18:$J$18)) -> #DIV/0! | Q31: =('Ver-Transição1'!$J$18/SUM('Ver-Transição1'!$G$18:$J$18)) -> #DIV/0!
A32: planilha de planejamento e controle do projeto | B32: =('Ver-Construção1'!$G$30/SUM('Ver-Construção1'!$G$30:$J$30)) -> 0.8 | C32: =('Ver-Construção1'!$H$30/SUM('Ver-Construção1'!$G$30:$J$30)) -> 0 | D32: =('Ver-Construção1'!$I$30/SUM('Ver-Construção1'!$G$30:$J$30)) -> 0 | E32: =('Ver-Construção1'!$J$30/SUM('Ver-Construção1'!$G$30:$J$30)) -> 0.2 | M32: roteiro de testes | N32: =('Ver-Transição1'!$G$23/SUM('Ver-Transição1'!$G$23:$J$23)) -> #DIV/0! | O32: =('Ver-Transição1'!$H$23/SUM('Ver-Transição1'!$G$23:$J$23)) -> #DIV/0! | P32: =('Ver-Transição1'!$I$23/SUM('Ver-Transição1'!$G$23:$J$23)) -> #DIV/0! | Q32: =('Ver-Transição1'!$J$23/SUM('Ver-Transição1'!$G$23:$J$23)) -> #DIV/0!
A33: repositório (itens de configuração) | B33: =('Ver-Construção1'!$G$36/SUM('Ver-Construção1'!$G$36:$J$36)) -> 1 | C33: =('Ver-Construção1'!$H$36/SUM('Ver-Construção1'!$G$36:$J$36)) -> 0 | D33: =('Ver-Construção1'!$I$36/SUM('Ver-Construção1'!$G$36:$J$36)) -> 0 | E33: =('Ver-Construção1'!$J$36/SUM('Ver-Construção1'!$G$36:$J$36)) -> 0 | M33: guia de implantação | N33: =('Ver-Transição1'!$G$26/SUM('Ver-Transição1'!$G$26:$J$26)) -> #DIV/0! | O33: =('Ver-Transição1'!$H$26/SUM('Ver-Transição1'!$G$26:$J$26)) -> #DIV/0! | P33: =('Ver-Transição1'!$I$26/SUM('Ver-Transição1'!$G$26:$J$26)) -> #DIV/0! | Q33: =('Ver-Transição1'!$J$26/SUM('Ver-Transição1'!$G$26:$J$26)) -> #DIV/0!
A34: requisição de mudanças | B34: =('Ver-Construção1'!$G$41/SUM('Ver-Construção1'!$G$41:$J$41)) -> 1 | C34: =('Ver-Construção1'!$H$41/SUM('Ver-Construção1'!$G$41:$J$41)) -> 0 | D34: =('Ver-Construção1'!$I$41/SUM('Ver-Construção1'!$G$41:$J$41)) -> 0 | E34: =('Ver-Construção1'!$J$41/SUM('Ver-Construção1'!$G$41:$J$41)) -> 0 | M34: manual do usuário (pode ser help on-line) | N34: =('Ver-Transição1'!$G$29/SUM('Ver-Transição1'!$G$29:$J$29)) -> #DIV/0! | O34: =('Ver-Transição1'!$H$29/SUM('Ver-Transição1'!$G$29:$J$29)) -> #DIV/0! | P34: =('Ver-Transição1'!$I$29/SUM('Ver-Transição1'!$G$29:$J$29)) -> #DIV/0! | Q34: =('Ver-Transição1'!$J$29/SUM('Ver-Transição1'!$G$29:$J$29)) -> #DIV/0!
M35: planilha de planejamento e controle do projeto | N35: =('Ver-Transição1'!$G$31/SUM('Ver-Transição1'!$G$31:$J$31)) -> #DIV/0! | O35: =('Ver-Transição1'!$H$31/SUM('Ver-Transição1'!$G$31:$J$31)) -> #DIV/0! | P35: =('Ver-Transição1'!$I$31/SUM('Ver-Transição1'!$G$31:$J$31)) -> #DIV/0! | Q35: =('Ver-Transição1'!$J$31/SUM('Ver-Transição1'!$G$31:$J$31)) -> #DIV/0!
M36: repositório (itens de configuração) | N36: =('Ver-Transição1'!$G$37/SUM('Ver-Transição1'!$G$37:$J$37)) -> #DIV/0! | O36: =('Ver-Transição1'!$H$37/SUM('Ver-Transição1'!$G$37:$J$37)) -> #DIV/0! | P36: =('Ver-Transição1'!$I$37/SUM('Ver-Transição1'!$G$37:$J$37)) -> #DIV/0! | Q36: =('Ver-Transição1'!$J$37/SUM('Ver-Transição1'!$G$37:$J$37)) -> #DIV/0!
M37: requisição de mudanças | N37: =('Ver-Transição1'!$G$42/SUM('Ver-Transição1'!$G$42:$J$42)) -> #DIV/0! | O37: =('Ver-Transição1'!$H$42/SUM('Ver-Transição1'!$G$42:$J$42)) -> #DIV/0! | P37: =('Ver-Transição1'!$I$42/SUM('Ver-Transição1'!$G$42:$J$42)) -> #DIV/0! | Q37: =('Ver-Transição1'!$J$42/SUM('Ver-Transição1'!$G$42:$J$42)) -> #DIV/0!

Sheet Ver-Iniciação1
A1: CheckList de Verificação de Projeto
A2: Data da Verificação: | D2: IAP - Indicador de Aderência ao Processo: | F2: =COUNTIF(D5:D41,"Sim")/(COUNTA(D5:D41)-COUNTIF(D5:D41,"NA")) -> 1
A3: Nome do Verificador: | D3: O ideal é que o índice de aderência ao processo tenha entre 70 e 100%
A4: Disciplina | B4: Qde. | C4: Itens de verificação | D4: Resultado | E4: Descrever o desvio | F4: Sugestão de melhoria
A5: Ambiente | C5: documentos não padronizados (templates, guias, leis, etc.) | G5: =COUNTIF(D6,"Sim") -> 0 | H5: =COUNTIF(D6,"Parcialmente") -> 0 | I5: =COUNTIF(D6,"Não") -> 0 | J5: =COUNTIF(D6,"NA") -> 1
B6: 1 | C6: Existe template para documento não previsto no SpinOff? | D6: NA
A7: Desenvolvimento - Requisitos | C7: visão | G7: =COUNTIF(D8:D12,"Sim") -> 5 | H7: =COUNTIF(D8:D12,"Parcialmente") -> 0 | I7: =COUNTIF(D8:D12,"Não") -> 0 | J7: =COUNTIF(D8:D12,"NA") -> 0
B8: 2 | C8: O artefato foi criado com o template atual e armazenado na pasta correta da estrutura do projeto? | D8: Sim
B9: 3 | C9: O objetivo, os problemas e as necessidades do cliente estão claras? | D9: Sim
B10: 4 | C10: As necessidades foram descritas como histórias de usuário? | D10: Sim
B11: 5 | C11: Fornece uma visão geral do sistema de forma clara e objetiva? | D11: Sim
B12: 6 | C12: Foram identificadas restrições de prazo, custo, tecnológica, ou qualquer outra e registradas no Visão? | D12: Sim
C13: modelo de caso de uso | G13: =COUNTIF(D14:D18,"Sim") -> 4 | H13: =COUNTIF(D14:D18,"Parcialmente") -> 0 | I13: =COUNTIF(D14:D18,"Não") -> 0 | J13: =COUNTIF(D14:D18,"NA") -> 1
B14: 7 | C14: O artefato foi criado com o template atual e armazenado na pasta correta da estrutura do projeto? | D14: Sim
B15: 8 | C15: O modelo de casos de uso, escopo do sistema em termos de funcionalidades, e respectivas permissões de acesso estão claros? | D15: Sim
B16: 9 | C16: Os casos de uso e atores possuem descrições claras e objetivas de forma a não necessitar que alguém explique-o verbalmente? | D16: Sim
B17: 10 | C17: Caso tenha sido criado o protótipo, ele foi armazenado na pasta correta da estrutura do projeto? | D17: NA
B18: 11 | C18: O escopo foi apresentado e aprovado pelo cliente ou representante? | D18: Sim
C19: especificações de requisitos (histórias do usuário)? | G19: =COUNTIF(D20:D21,"Sim") -> 2 | H19: =COUNTIF(D20:D21,"Parcialmente") -> 0 | I19: =COUNTIF(D20:D21,"Não") -> 0 | J19: =COUNTIF(D20:D21,"NA") -> 0
B20: 12 | C20: Se criado, o artefato usou o template atual e foi armazenado na pasta correta da estrutura do projeto? | D20: Sim
B21: 13 | C21: Se criados, as especificações para os casos de uso/histórias de usuário são testáveis, ou seja, é possível identificar as entradas e verificar se as saída estão corretas? | D21: Sim
C22: glossário | G22: =COUNTIF(D23:D24,"Sim") -> 0 | H22: =COUNTIF(D23:D24,"Parcialmente") -> 0 | I22: =COUNTIF(D23:D24,"Não") -> 0 | J22: =COUNTIF(D23:D24,"NA") -> 2
B23: 14 | C23: O artefato foi criado com o template atual e armazenado na pasta correta da estrutura do projeto? | D23: NA
B24: 15 | C24: As descrições dos termos estão claras? | D24: NA
C25: atas de reuniões | G25: =COUNTIF(D26:D27,"Sim") -> 0 | H25: =COUNTIF(D26:D27,"Parcialmente") -> 0 | I25: =COUNTIF(D26:D27,"Não") -> 0 | J25: =COUNTIF(D26:D27,"NA") -> 2
B26: 16 | C26: O artefato foi criado com o template atual e armazenado na pasta correta da estrutura do projeto? | D26: NA
B27: 17 | C27: As atas das reuniões de levantamento de requisitos foram aprovadas? | D27: NA
C28: planilha de planejamento e controle do projeto | G28: =COUNTIF(D29:D36,"Sim") -> 8 | H28: =COUNTIF(D29:D36,"Parcialmente") -> 0 | I28: =COUNTIF(D29:D36,"Não") -> 0 | J28: =COUNTIF(D29:D36,"NA") -> 0
B29: 21 | C29: O artefato foi criado com o template atual e armazenado na pasta correta da estrutura do projeto? | D29: Sim
B30: 22 | C30: A equipe foi definida com seus respectivos e-mails? | D30: Sim
B31: 23 | C31: O backlog do produto foi criado com todos os Casos de Uso? | D31: Sim
B32: 24 | C32: Foi feita a estimativa do Backlog do Produto? | D32: Sim
B33: 25 | C33: Foi feita a priorização do Backlog do Produto? | D33: Sim
B34: 26 | C34: O plano de entregas foi definido e documentado e corresponde ao número de sprints planejado? | D34: Sim
B35: 27 | C35: O plano de gerenciamento de riscos foi elaborado e considerou as restrições registradas no Visão? | D35: Sim
B36: 28 | C36: O planejamento foi apresentado e aprovado pelo cliente ou representante? | D36: Sim
A37: Gerenciamento de Configuração e Mudanças | C37: repositório (itens de configuração) | G37: =COUNTIF(D38:D41,"Sim") -> 4 | H37: =COUNTIF(D38:D41,"Parcialmente") -> 0 | I37: =COUNTIF(D38:D41,"Não") -> 0 | J37: =COUNTIF(D38:D41,"NA") -> 0
B38: 30 | C38: A estrutura do projeto (repositório) foi criada com o template atual e está sicronizada com o servidor? | D38: Sim
B39: 31 | C39: Os artefatos estão nos locais corretos conforme guia-mapeamento de processo x produto? | D39: Sim
B40: 32 | C40: Os artefatos estão nomeados conforme guia-políticas de GC? | D40: Sim
...

Sheet Ver-Elaboração1
A1: CheckList de Verificação de Projeto
A2: Data da Verificação: | D2: IAP - Indicador de Aderência ao Processo: | F2: =COUNTIF(D5:D41,"Sim")/(COUNTA(D5:D42)-COUNTIF(D5:D42,"NA")) -> 0.82608696
A3: Nome do Verificador: | D3: O ideal é que o índice de aderência ao processo tenha entre 70 e 100%
A4: Disciplina | B4: Qde. | C4: Itens de verificação | D4: Resultado | E4: Descrever o desvio | F4: Sugestão de melhoria
A5: Desenvolvimento - Requisitos | C5: visão
B6: 1 | C6: O visão foi atualizado devido a mudança de escopo? | D6: Não | G6: =COUNTIF(D6,"Sim") -> 0 | H6: =COUNTIF(D6,"Parcialmente") -> 0 | I6: =COUNTIF(D6,"Não") -> 1 | J6: =COUNTIF(D6,"NA") -> 0
C7: modelo de caso de uso
B8: 2 | C8: O modelo de casos de uso, escopo do sistema, foi atualizado conforme as mudanças? | D8: Sim | G8: =COUNTIF(D8,"Sim") -> 1 | H8: =COUNTIF(D8,"Parcialmente") -> 0 | I8: =COUNTIF(D8,"Não") -> 0 | J8: =COUNTIF(D8,"NA") -> 0
B9: 3 | C9: Os casos de uso e atores foram documentados (especificados) com descrição dos elementos UML. | D9: Sim
C10: especificações de requisitos (histórias do usuário)?
B11: 4 | C11: As especificações dos casos de uso/histórias de usuário foram atualizadas conforme a implementação? | D11: Sim | G11: =COUNTIF(D11:D14,"Sim") -> 3 | H11: =COUNTIF(D11:D14,"Parcialmente") -> 0 | I11: =COUNTIF(D11:D14,"Não") -> 0 | J11: =COUNTIF(D11:D14,"NA") -> 1
B12: 5 | C12: Foi criado/atualizado o modelo de negócio das entidades? (diagrama de classes) | D12: NA
B13: 6 | C13: As novas especificações, modelos e protótipos foram aprovados pelo cliente? | D13: Sim
B14: 7 | C14: O caso de uso/história de usuário escolhido para definir e testar a arquitetura foi especificado? | D14: Sim
C15: glossário
B16: 7 | C16: Foi atualizado? | D16: NA | G16: =COUNTIF(D16,"Sim") -> 0 | H16: =COUNTIF(D16,"Parcialmente") -> 0 | I16: =COUNTIF(D16,"Não") -> 0 | J16: =COUNTIF(D16,"NA") -> 1
A17: Desenvolvimento - Análise e Design | C17: modelo de arquitetura
B18: 9 | C18: O caso de uso escolhido para definir e testar a arquitetura foi implementado e testado? | D18: Sim | G18: =COUNTIF(D18:D21,"Sim") -> 3 | H18: =COUNTIF(D18:D21,"Parcialmente") -> 0 | I18: =COUNTIF(D18:D21,"Não") -> 0 | J18: =COUNTIF(D18:D21,"NA") -> 1
B19: 10 | C19: Foram criados diagramas de classes, de arquitetura, de pacotes e de deployment? | D19: Sim
B20: 11 | C20: Os requisitos suplementares (não funcionais) foram especificados e utilizados na definição da arquitetura? | D20: NA
B21: 12 | C21: Foi criado o Modelo de Negócio (diagrama de classes com todas as entidades identificadas) ou um DER (diagrama de entidade relacionamento) | D21: Sim
A22: Desenvolvimento - Implementação | C22: codigo fonte
B23: 17 | C23: O caso de uso escolhido para definir e testar a arquitetura foi implementado e testado? | D23: Sim | G23: =COUNTIF(D23:D27,"Sim") -> 3 | H23: =COUNTIF(D23:D27,"Parcialmente") -> 0 | I23: =COUNTIF(D23:D27,"Não") -> 0 | J23: =COUNTIF(D23:D27,"NA") -> 2
B24: 18 | C24: O código respeita o modelo de arquitetura, inclusive nomeação de classes, atributos, relacionamentos e pacotes? | D24: Sim
B25: 19 | C25: O código está dentro dos padrões de codificação, conforme as convenções de código da linguagem? | D25: Sim
B26: 21 | C26: Foram criados os testes unitários dos controladores? | D26: NA
B27: 22 | C27: Os testes unitários foram executados? | D27: NA
A28: Gerenciamento de Projetos | C28: planilha de planejamento e controle do projeto
B29: 23 | C29: Foi feito o planejamento do Sprint? | D29: Sim | G29: =COUNTIF(D29:D34,"Sim") -> 4 | H29: =COUNTIF(D29:D34,"Parcialmente") -> 0 | I29: =COUNTIF(D29:D34,"Não") -> 2 | J29: =COUNTIF(D29:D34,"NA") -> 0
B30: 24 | C30: Foi refeita a estimativa e a priorização no Backlog do Sprint? | D30: Não
B31: 25 | C31: No Backlog do Produto foi incluído mais alguma atividade, estimado e priorizado? | D31: Não
B32: 26 | C32: O plano de entregas foi atualizado? | D32: Sim
B33: 27 | C33: O plano de gerenciamento de riscos foi atualizado? | D33: Sim
B34: 28 | C34: Foram feitas as reuniões de Revisão do Produto e Processo? | D34: Sim
A35: Gerenciamento de Configuração e Mudanças | C35: repositório (itens de configuração)
B36: 29 | C36: Os artefatos estão nos locais corretos conforme guia-mapeamento de processo x produto? | D36: Sim | G36: =COUNTIF(D36:D38,"Sim") -> 3 | H36: =COUNTIF(D36:D38,"Parcialmente") -> 0 | I36: =COUNTIF(D36:D38,"Não") -> 0 | J36: =COUNTIF(D36:D38,"NA") -> 0
B37: 30 | C37: Os artefatos estão nomeados conforme guia-políticas de GC? | D37: Sim
B38: 31 | C38: Os históricos de atualizações dos artefatos, na ferramenta, possuem descrição do que foi alterado? | D38: Sim
C39: requisição de mudanças
B40: 32 | C40: As mudanças de escopo foram registradas no Backlog do produto? | D40: Sim | G40: =COUNTIF(D40:D41,"Sim") -> 1 | H40: =COUNTIF(D40:D41,"Parcialmente") -> 0 | I40: =COUNTIF(D40:D41,"Não") -> 1 | J40: =COUNTIF(D40:D41,"NA") -> 0
...

Sheet Ver-Construção1
A1: CheckList de Verificação de Projeto
A2: Data da Verificação: | D2: IAP - Indicador de Aderência ao Processo: | F2: =COUNTIF(D5:D42,"Sim")/(COUNTA(D5:D41)-COUNTIF(D5:D41,"NA")) -> 1.0416667
A3: Nome do Verificador: | D3: O ideal é que o índice de aderência ao processo tenha entre 70 e 100%
A4: Disciplina | B4: Qde. | C4: Itens de verificação | D4: Resultado | E4: Descrever o desvio | F4: Sugestão de melhoria
A5: Desenvolvimento - Requisitos | C5: visão
B6: 1 | C6: O visão foi atualizado devido a mudança de escopo? | D6: NA | G6: =COUNTIF(D6,"Sim") -> 0 | H6: =COUNTIF(D6,"Parcialmente") -> 0 | I6: =COUNTIF(D6,"Não") -> 0 | J6: =COUNTIF(D6,"NA") -> 1
C7: modelo de caso de uso
B8: 2 | C8: O modelo de casos de uso, escopo do sistema, foi atualizado conforme as mudanças? | D8: Sim | G8: =COUNTIF(D8,"Sim") -> 1 | H8: =COUNTIF(D8,"Parcialmente") -> 0 | I8: =COUNTIF(D8,"Não") -> 0 | J8: =COUNTIF(D8,"NA") -> 0
C9: especificações de requisitos (histórias do usuário)?
B10: 3 | C10: As especificações dos casos de uso/histórias de usuário foram atualizadas conforme a implementação? | D10: Sim | G10: =COUNTIF(D10:D12,"Sim") -> 3 | H10: =COUNTIF(D10:D12,"Parcialmente") -> 0 | I10: =COUNTIF(D10:D12,"Não") -> 0 | J10: =COUNTIF(D10:D12,"NA") -> 0
B11: 4 | C11: Os diagramas de de casos de uso e classes foram atualizados conforme a implementação? (diagrama de classes ou DER) | D11: Sim
B12: 5 | C12: As novas especificações, modelos e protótipos foram aprovados pelo cliente? | D12: Sim
C13: glossário
B14: 6 | C14: Foi atualizado? | D14: NA | G14: =COUNTIF(D14,"Sim") -> 0 | H14: =COUNTIF(D14,"Parcialmente") -> 0 | I14: =COUNTIF(D14,"Não") -> 0 | J14: =COUNTIF(D14,"NA") -> 1
A15: Desenvolvimento - Análise e Design | C15: modelo de arquitetura
B16: 8 | C16: O modelo de arquitetura foi atualizado? | D16: Sim | G16: =COUNTIF(D16,"Sim") -> 1 | H16: =COUNTIF(D16,"Parcialmente") -> 0 | I16: =COUNTIF(D16,"Não") -> 0 | J16: =COUNTIF(D16,"NA") -> 0
A17: Desenvolvimento - Implementação | C17: codigo fonte
B18: 11 | C18: Os diagramas de classe foram atualizados conforme a codificação realizada? | D18: Sim | G18: =COUNTIF(D18:D22,"Sim") -> 5 | H18: =COUNTIF(D18:D22,"Parcialmente") -> 0 | I18: =COUNTIF(D18:D22,"Não") -> 0 | J18: =COUNTIF(D18:D22,"NA") -> 0
B19: 13 | C19: O código respeita o modelo de arquitetura, inclusive nomeação de classes, atributos, relacionamentos e pacotes? | D19: Sim
B20: 14 | C20: O código está dentro dos padrões de codificação, conforme as convenções de código da linguagem? | D20: Sim
B21: 15 | C21: Foram criados os testes unitários dos controladores? | D21: Sim
B22: 16 | C22: Os testes unitários foram executados? | D22: Sim
A23: Desenvolvimento - Testes | C23: roteiro de testes
B24: 17 | C24: O artefato foi criado com o template atual e armazenado na pasta correta da estrutura do projeto? | D24: Sim | G24: =COUNTIF(D24:D28,"Sim") -> 5 | H24: =COUNTIF(D24:D28,"Parcialmente") -> 0 | I24: =COUNTIF(D24:D28,"Não") -> 0 | J24: =COUNTIF(D24:D28,"NA") -> 0
B25: 18 | C25: Possui um roteiro com casos de testes para cada caso de uso ou história de usuário? | D25: Sim
B26: 19 | C26: Os dados de entrada e resultados esperados estão definidos? | D26: Sim
B27: 21 | C27: Existem evidências de execução dos testes? | D27: Sim
B28: 22 | C28: Os testes realizados foram registrados no roteiro de testes? | D28: Sim
A29: Gerenciamento de Projetos | C29: planilha de planejamento e controle do projeto
B30: 24 | C30: Foi feito o planejamento do Sprint? | D30: Sim | G30: =COUNTIF(D30:D34,"Sim") -> 4 | H30: =COUNTIF(D30:D34,"Parcialmente") -> 0 | I30: =COUNTIF(D30:D34,"Não") -> 0 | J30: =COUNTIF(D30:D34,"NA") -> 1
B31: 26 | C31: O Backlog do Produto foi alterado, caso tenham sido incluidas ou removidas tarefas? | D31: Sim
B32: 27 | C32: O plano de entregas foi atualizado? Corresponde ao número de sprints? | D32: Sim
B33: 28 | C33: O plano de gerenciamento de riscos foi atualizado? | D33: NA
B34: 29 | C34: Foram feitas as reuniões de Revisão do Produto e Processo? | D34: Sim
A35: Gerenciamento de Configuração e Mudanças | C35: repositório (itens de configuração)
B36: 30 | C36: Os artefatos estão nos locais corretos conforme guia-mapeamento de processo x produto? | D36: Sim | G36: =COUNTIF(D36:D38,"Sim") -> 3 | H36: =COUNTIF(D36:D38,"Parcialmente") -> 0 | I36: =COUNTIF(D36:D38,"Não") -> 0 | J36: =COUNTIF(D36:D38,"NA") -> 0
B37: 31 | C37: Os artefatos estão nomeados conforme guia-políticas de GC? | D37: Sim
B38: 32 | C38: Os históricos de atualizações dos artefatos, na ferramenta, possuem descrição do que foi alterado? | D38: Sim
C39: Existe histórico de alterações das configurações base? | D39: Sim
C40: requisição de mudanças
...

Sheet Ver-Transição1
A1: CheckList de Verificação de Projeto
A2: Data da Verificação: | D2: IAP - Indicador de Aderência ao Processo: | F2: =COUNTIF(D5:D43,"Sim")/(COUNTA(D5:D43)-COUNTIF(D5:D43,"NA")) -> #DIV/0!
A3: Nome do Verificador: | D3: O ideal é que o índice de aderência ao processo tenha entre 70 e 100%
A4: Disciplina | B4: Qde. | C4: Itens de verificação | D4: Resultado | E4: Descrever o desvio | F4: Sugestão de melhoria
A5: Desenvolvimento - Requisitos | C5: visão
B6: 1 | C6: O visão foi atualizado devido a mudança de escopo? | G6: =COUNTIF(D6,"Sim") -> 0 | H6: =COUNTIF(D6,"Parcialmente") -> 0 | I6: =COUNTIF(D6,"Não") -> 0 | J6: =COUNTIF(D6,"NA") -> 0
C7: modelo de caso de uso
B8: 2 | C8: O modelo de casos de uso, escopo do sistema, foi atualizado conforme as mudanças? | G8: =COUNTIF(D8,"Sim") -> 0 | H8: =COUNTIF(D8,"Parcialmente") -> 0 | I8: =COUNTIF(D8,"Não") -> 0 | J8: =COUNTIF(D8,"NA") -> 0
C9: especificações de requisitos (casos de uso e/ou histórias do usuário)?
B10: 3 | C10: As especificações dos casos de uso/histórias de usuário foram atualizadas conforme a implementação? | G10: =COUNTIF(D10:D12,"Sim") -> 0 | H10: =COUNTIF(D10:D12,"Parcialmente") -> 0 | I10: =COUNTIF(D10:D12,"Não") -> 0 | J10: =COUNTIF(D10:D12,"NA") -> 0
B11: 4 | C11: Os diagramas de de casos de uso e classes foram atualizados conforme a implementação? (diagrama de classes ou DER)
B12: 5 | C12: As novas especificações, modelos e protótipos foram aprovados pelo cliente?
C13: glossário
B14: 6 | C14: Foi atualizado? | G14: =COUNTIF(D14,"Sim") -> 0 | H14: =COUNTIF(D14,"Parcialmente") -> 0 | I14: =COUNTIF(D14,"Não") -> 0 | J14: =COUNTIF(D14,"NA") -> 0
A15: Desenvolvimento - Análise e Design | C15: modelo de arquitetura
B16: 8 | C16: O modelo de arquitetura foi atualizado? | G16: =COUNTIF(D16,"Sim") -> 0 | H16: =COUNTIF(D16,"Parcialmente") -> 0 | I16: =COUNTIF(D16,"Não") -> 0 | J16: =COUNTIF(D16,"NA") -> 0
A17: Desenvolvimento - Implementação | C17: codigo fonte
B18: 9 | C18: Foi realizado refinamentos no código para melhorar eficiência ou corrigir bugs? | G18: =COUNTIF(D18:D21,"Sim") -> 0 | H18: =COUNTIF(D18:D21,"Parcialmente") -> 0 | I18: =COUNTIF(D18:D21,"Não") -> 0 | J18: =COUNTIF(D18:D21,"NA") -> 0
B19: 10 | C19: Os diagramas de classes foram atualizados?
B20: 11 | C20: O código está dentro dos padrões de codificação, conforme as convenções de código da linguagem?
B21: 13 | C21: Os testes unitários foram executados, todos passaram?
A22: Desenvolvimento - Testes | C22: roteiro de testes
B23: 14 | C23: Os roteiros de testes foram atualizados e executados? | G23: =COUNTIF(D23:D24,"Sim") -> 0 | H23: =COUNTIF(D23:D24,"Parcialmente") -> 0 | I23: =COUNTIF(D23:D24,"Não") -> 0 | J23: =COUNTIF(D23:D24,"NA") -> 0
B24: 15 | C24: Os testes realizados foram registrados no roteiro de testes?
A25: Desenvolvimento - Implantação | C25: guia de implantação
B26: 24 | C26: O artefato foi criado com o template atual e armazenado na pasta correta da estrutura do projeto? | G26: =COUNTIF(D26:D27,"Sim") -> 0 | H26: =COUNTIF(D26:D27,"Parcialmente") -> 0 | I26: =COUNTIF(D26:D27,"Não") -> 0 | J26: =COUNTIF(D26:D27,"NA") -> 0
B27: 25 | C27: O guia de implantação foi criado para implantar o produto (subproduto) com software, hardware, etc. necessários para a implantação em ambiente de produção?
C28: manual do usuário (pode ser help on-line)
B29: 26 | C29: O artefato foi criado com o template atual e armazenado na pasta correta da estrutura do projeto? | G29: =COUNTIF(D29,"Sim") -> 0 | H29: =COUNTIF(D29,"Parcialmente") -> 0 | I29: =COUNTIF(D29,"Não") -> 0 | J29: =COUNTIF(D29,"NA") -> 0
A30: Gerenciamento de Projetos | C30: planilha de planejamento e controle do projeto
B31: 19 | C31: Foi feito o planejamento do Sprint? | G31: =COUNTIF(D31:D35,"Sim") -> 0 | H31: =COUNTIF(D31:D35,"Parcialmente") -> 0 | I31: =COUNTIF(D31:D35,"Não") -> 0 | J31: =COUNTIF(D31:D35,"NA") -> 0
B32: 20 | C32: O Backlog do Produto foi alterado, caso tenham sido incluidas ou removidas tarefas?
B33: 21 | C33: O plano de entregas foi atualizado? Corresponde ao número de sprints?
B34: 24 | C34: Foram realizados os testes de aceitação por parte do usuário final?
B35: 25 | C35: Foram feitas as reuniões de Revisão do Produto e Processo?
A36: Gerenciamento de Configuração e Mudanças | C36: repositório (itens de configuração)
B37: 26 | C37: Os artefatos estão nos locais corretos conforme guia-mapeamento de processo x produto? | G37: =COUNTIF(D37:D39,"Sim") -> 0 | H37: =COUNTIF(D37:D39,"Parcialmente") -> 0 | I37: =COUNTIF(D37:D39,"Não") -> 0 | J37: =COUNTIF(D37:D39,"NA") -> 0
B38: 27 | C38: Os artefatos estão nomeados conforme guia-políticas de GC?
B39: 28 | C39: Os históricos de atualizações dos artefatos, na ferramenta, possuem descrição do que foi alterado?
C40: Existe histórico de alterações das configurações base?
...
